<?xml version="1.0" ?>
<robot name="meu_robo">
  <link name="base"/>

  <joint name="joint1" type="revolute">
    <parent link="base"/>
    <child link="link1"/>
    <origin xyz="0 0 0.1" rpy="0 0 0"/>
    <axis xyz="0 0 1"/>
    <limit effort="1" lower="-3.14" upper="3.14" velocity="1"/>
  </joint>

  <link name="link1">
    <visual>
      <geometry>
        <box size="0.5 0.1 0.1"/>
      </geometry>
      <origin xyz="0.25 0 0" rpy="0 0 0"/>
    </visual>
  </link>

  <joint name="joint2" type="revolute">
    <parent link="link1"/>
    <child link="link2"/>
    <origin xyz="0.5 0 0" rpy="0 0 0"/>
    <axis xyz="0 0 1"/>
    <limit effort="1" lower="-3.14" upper="3.14" velocity="1"/>
  </joint>

  <link name="link2">
    <visual>
      <geometry>
        <box size="0.5 0.1 0.1"/>
      </geometry>
      <origin xyz="0.25 0 0" rpy="0 0 0"/>
    </visual>
  </link>
</robot>
